Workbook

Sheet Executive Summary
A1: Worldpay Master Account Plan — Executive Overview
A2: Updated 2026-09-30 | Prepared for the WP BackBook ICP Review
A4: Portfolio accounts | C4: Previously scored | E4: Supplemental additions | G4: Meeting-focus additions
A5: =COUNTA('Ranked Portfolio'!C5:C500) -> 115 | C5: =COUNT('Ranked Portfolio'!G5:G500) -> 30 | E5: =COUNTIF('Ranked Portfolio'!B5:B500,"Unranked") -> 85 | G5: =COUNTIF('Added Accounts Overview'!A5:A200,"A*") -> 18
A7: Meeting objective
A8: Agree which supplemental accounts belong in the enterprise ICP, assign an owner/RM path, and separate corporate chain opportunities from single-franchise or local merchant records.
A10: What changed
A11: The plan now accommodates 115 accounts: the original 30 scored opportunities plus 85 supplemental Worldpay backbook accounts. The supplemental rows now distinguish brand footprint from the exact WP merchant/entity footprint, use normalized operating segments, and explicitly flag Worldpay relationship ownership as unconfirmed until the WP team names an owner.
A13: Priority added-account themes
A14: 1) Scale: Buffalo Wild Wings and Culver’s are the clearest large-system additions. 2) Portfolio leverage: McAlister’s, Moe’s, Jamba and Carvel sit within GoTo Foods. 3) Regional scale: Ruby Tuesday, Logan’s Roadhouse, Fazoli’s, Sarku Japan, Chuy’s and Tijuana Flats warrant qualification. 4) Long tail: many LLC/franchisee records require entity and buying-authority validation before pursuit.
A17: Competitive / technology read
A18: Buffalo Wild Wings renewed NCR Voyix for POS in July 2025, so near-term POS displacement should not be assumed. Culver’s is recorded in RBB with PAR Brink. Fazoli’s has a PAR/Olo/Punchh stack on file. GoTo Foods brands should be coordinated as a platform-level motion rather than four unrelated cold pursuits.
A21: Decisions needed today
A22: • For every supplemental row, name the Worldpay relationship owner—even if that person is not the formal RM. • Confirm the merchant/legal entity and whether WP coverage is enterprise, franchisee, or single-site. • Validate location scope before using brand-wide counts for legal entities or numbered stores. • Select 5–10 accounts for full discovery; keep unresolved merchant records in qualification. • Confirm how attrition and dyssynergy flags should affect pursuit.
A27: Research discipline
A28: “Meeting focus” is a research-priority label, not a forecast or approved opportunity score. Facts are sourced from the Worldpay workbook, RBB ecosystem intelligence and cited public sources. Unknown buying events, contract dates and account ownership remain explicit qualification gaps.

Sheet Dashboard
A1: Worldpay Portfolio Dashboard
A2: 115-account portfolio | scored opportunities plus supplemental qualification targets
B4: Total accounts | E4: Scored portfolio | H4: Supplemental | K4: A-priority additions
B5: =COUNTA('Ranked Portfolio'!C5:C500) -> 115 | E5: =COUNT('Ranked Portfolio'!G5:G500) -> 30 | H5: =COUNTIF('Ranked Portfolio'!B5:B500,"Unranked") -> 85 | K5: =COUNTIF('Added Accounts Overview'!A5:A200,"A*") -> 18
B7: WP owner confirmed | E7: Public footprints refreshed | H7: Needs WP owner | K7: Entity/site records
B8: =COUNTIFS('Added Accounts Overview'!Q5:Q200,"<>Unconfirmed — ask Worldpay",'Added Accounts Overview'!Q5:Q200,"<>") -> 0 | E8: =COUNTIF('Added Accounts Overview'!L5:L200,"Public footprint refreshed*") -> 7 | H8: =COUNTIF('Added Accounts Overview'!Q5:Q200,"Unconfirmed — ask Worldpay") -> 85 | K8: =COUNTIF('Added Accounts Overview'!N5:N200,"Legal entity*") -> 29
B11: Added-account meeting priority | E11: Added accounts by segment
B12: A — Meeting focus | C12: =COUNTIF('Added Accounts Overview'!A5:A200,"A*") -> 18 | E12: Coffee | F12: =COUNTIF('Added Accounts Overview'!D5:D200,"Coffee") -> 0
B13: B — Qualify | C13: =COUNTIF('Added Accounts Overview'!A5:A200,"B*") -> 29 | E13: Burger | F13: =COUNTIF('Added Accounts Overview'!D5:D200,"Burger") -> 1
B14: C — Validate / deprioritize | C14: =COUNTIF('Added Accounts Overview'!A5:A200,"C*") -> 38 | E14: Mexican | F14: =COUNTIF('Added Accounts Overview'!D5:D200,"Mexican") -> 1
E15: Sandwich | F15: =COUNTIF('Added Accounts Overview'!D5:D200,"Sandwich") -> 1
E16: Family Dining | F16: =COUNTIF('Added Accounts Overview'!D5:D200,"Family Dining") -> 3
E17: Full-Service Dining | F17: =COUNTIF('Added Accounts Overview'!D5:D200,"Full-Service Dining") -> 1
E18: Pizza | F18: =COUNTIF('Added Accounts Overview'!D5:D200,"Pizza") -> 2
E19: Dessert | F19: =COUNTIF('Added Accounts Overview'!D5:D200,"Dessert") -> 1
E20: Other | F20: =COUNTA('Added Accounts Overview'!B5:B200)-SUM(F12:F19) -> 75
B23: Brand footprint and WP merchant footprint are separate fields. No supplemental account should be treated as owned until Worldpay names the relationship owner and confirms enterprise vs. franchisee/site scope.

Sheet Added Accounts Overview
A1: Worldpay Supplemental Accounts — Meeting Overview
A2: Prepared 2026-09-30 for WP BackBook ICP Review. Priority is research/meeting triage, not an approved sales score.
A4: Meeting Priority | B4: Account | C4: Source Relevance | D4: Sub-segment | E4: Technomic Rank | F4: Approx. Units | G4: Parent / Platform | H4: Research Summary | I4: Known Technology | J4: Worldpay Posture | K4: Recommended Next Action | L4: Research Status | M4: Source References | N4: Account Type | O4: Location Scope | P4: Location Confidence | Q4: WP Relationship Owner | R4: Internal Clarification Needed
A5: A — Meeting focus | B5: Buffalo Wild Wings | C5: Yes | D5: Family Dining | E5: 28 | F5: 1323 | G5: Inspire Brands | H5: Technomic rank 28; ~1,323 units. Family Dining account from Worldpay backbook. Platform/owner: Inspire Brands. | I5: POS: NCR Voyix partnership renewed July 2025; kds_kitchen_ops: Jolt | J5: Source-marked synergy fit | K5: Confirm Worldpay RM, processing scope and renewal dates; map enterprise technology owner and POS/payments decision window. | L5: Meeting-ready | M5: RBB ecosystem intelligence, 2026-09-30 | https://www.ncrvoyix.com/newsroom/buffalo-wild-wings-renews-partnership-with-ncr-voyix-as-partner-for-pos-platform | N5: Brand / chain | O5: Brand/system footprint from existing RBB research | P5: Medium | Q5: Unconfirmed — ask Worldpay | R5: Who at Worldpay owns this relationship, what merchant IDs/legal entities are in scope, and is coverage enterprise, franchisee, or a single site?
A6: A — Meeting focus | B6: Culver'S | C6: Yes | D6: Burger | E6: 29 | F6: 997 | G6: Culver Franchising System | H6: Technomic rank 29; ~997 units. Burger account from Worldpay backbook. Platform/owner: Culver Franchising System. | I6: POS: PAR Technology (Brink); POS Hardware: PAR; kds_kitchen_ops: Jolt | J6: Source-marked synergy fit; WP dyssynergy flag present | K6: Confirm Worldpay RM, processing scope and renewal dates; map enterprise technology owner and POS/payments decision window. | L6: Meeting-ready | M6: RBB ecosystem intelligence, 2026-09-30 | https://www.culvers.com/stories/signature-stories/culvers-locations-by-state | N6: Brand / chain | O6: Brand/system footprint from existing RBB research | P6: Medium | Q6: Unconfirmed — ask Worldpay | R6: Who at Worldpay owns this relationship, what merchant IDs/legal entities are in scope, and is coverage enterprise, franchisee, or a single site?
A7: A — Meeting focus | B7: Mcalisters Deli | C7: Yes | D7: Sandwich | E7: 59 | F7: 560 | G7: GoTo Foods | H7: Technomic rank 59; ~560 units. Sandwich account from Worldpay backbook. Platform/owner: GoTo Foods. | I7: Loyalty: PAR Technology (Punchh) | J7: Source-marked synergy fit | K7: Confirm Worldpay RM, processing scope and renewal dates; map enterprise technology owner and POS/payments decision window. | L7: Meeting-ready | M7: RBB ecosystem intelligence, 2026-09-30 | https://development.gotofoods.com/wp-content/uploads/2025/03/GTF_Digital_IncentiveBrochure2025.pdf | N7: Brand / chain | O7: Brand/system footprint from existing RBB research | P7: Medium | Q7: Unconfirmed — ask Worldpay | R7: Who at Worldpay owns this relationship, what merchant IDs/legal entities are in scope, and is coverage enterprise, franchisee, or a single site?
A8: A — Meeting focus | B8: Moes Southwest Grill | C8: Yes | D8: Mexican | E8: 78 | F8: 596 | G8: GoTo Foods | H8: Technomic rank 78; ~596 units. Mexican account from Worldpay backbook. Platform/owner: GoTo Foods. | I8: Loyalty: PAR Technology (Punchh); kiosks: Nextep Systems | J8: Source-marked synergy fit | K8: Confirm Worldpay RM, processing scope and renewal dates; map enterprise technology owner and POS/payments decision window. | L8: Meeting-ready | M8: RBB ecosystem intelligence, 2026-09-30 | https://development.gotofoods.com/wp-content/uploads/2025/03/GTF_Digital_IncentiveBrochure2025.pdf | N8: Brand / chain | O8: Brand/system footprint from existing RBB research | P8: Medium | Q8: Unconfirmed — ask Worldpay | R8: Who at Worldpay owns this relationship, what merchant IDs/legal entities are in scope, and is coverage enterprise, franchisee, or a single site?
A9: A — Meeting focus | B9: Chuy'S | C9: Yes | D9: Casual Dining — Mexican | E9: 110 | F9: 104 | H9: Technomic rank 110; ~104 units. Mexican account from Worldpay backbook. | I9: Back Office: PAR Technology (Data Central) | J9: Source-marked synergy fit | K9: Confirm Worldpay RM, processing scope and renewal dates; map enterprise technology owner and POS/payments decision window. | L9: Meeting-ready | M9: RBB ecosystem intelligence, 2026-09-30 | N9: Brand / chain | O9: Brand/system footprint from existing RBB research | P9: Medium | Q9: Unconfirmed — ask Worldpay | R9: Who at Worldpay owns this relationship, what merchant IDs/legal entities are in scope, and is coverage enterprise, franchisee, or a single site?
A10: A — Meeting focus | B10: Ruby Tuesday | C10: Yes | D10: Casual Dining | E10: 159 | F10: 212 | H10: Technomic rank 159; ~212 units. Full-Service Dining account from Worldpay backbook. | I10: No non-Worldpay technology verified | J10: Source-marked synergy fit; WP dyssynergy flag present | K10: Confirm Worldpay RM, processing scope and renewal dates; map enterprise technology owner and POS/payments decision window. | L10: Meeting-ready | M10: RBB ecosystem intelligence, 2026-09-30 | https://www.rubytuesday.com/locations/ | N10: Brand / chain | O10: Brand/system footprint from existing RBB research | P10: Medium | Q10: Unconfirmed — ask Worldpay | R10: Who at Worldpay owns this relationship, what merchant IDs/legal entities are in scope, and is coverage enterprise, franchisee, or a single site?
A11: A — Meeting focus | B11: Fazolis | C11: Yes | D11: Fast Casual — Italian | E11: 165 | F11: 196 | G11: FAT Brands | H11: Technomic rank 165; ~196 units. Family Dining account from Worldpay backbook. Platform/owner: FAT Brands. | I11: Online Ordering: Olo — Olo (historical scoped evidence); POS: PAR Technology (Brink); POS Hardware: PAR Technology (Hardware / Break Fix); Loyalty: PAR Technology (Punchh); drive_thru_ai: ConverseNow | J11: Source-marked synergy fit | K11: Confirm Worldpay RM, processing scope and renewal dates; map enterprise technology owner and POS/payments decision window. | L11: Meeting-ready | M11: RBB ecosystem intelligence, 2026-09-30 | https://ir.fatbrands.com/news/news-details/2025/Fazolis-Debuts-First-International-Location-in-Canada/default.aspx | N11: Brand / chain | O11: Brand/system footprint from existing RBB research | P11: Medium | Q11: Unconfirmed — ask Worldpay | R11: Who at Worldpay owns this relationship, what merchant IDs/legal entities are in scope, and is coverage enterprise, franchisee, or a single site?
A12: A — Meeting focus | B12: La Madeleine | C12: Yes | D12: Fast Casual — Bakery Café | E12: 213 | F12: 91 | H12: Technomic rank 213; ~91 units. Full-Service Dining account from Worldpay backbook. | I12: Online Ordering: Olo | J12: Source-marked synergy fit | K12: Confirm Worldpay RM, processing scope and renewal dates; map enterprise technology owner and POS/payments decision window. | L12: Meeting-ready | M12: RBB ecosystem intelligence, 2026-09-30 | N12: Brand / chain | O12: Brand/system footprint from existing RBB research | P12: Medium | Q12: Unconfirmed — ask Worldpay | R12: Who at Worldpay owns this relationship, what merchant IDs/legal entities are in scope, and is coverage enterprise, franchisee, or a single site?
A13: A — Meeting focus | B13: Sarku Japan | C13: Yes | D13: Fast Casual — Asian | E13: 261 | F13: 137 | H13: Technomic rank 261; ~137 units. Asian account from Worldpay backbook. | I13: No non-Worldpay technology verified | J13: Source-marked synergy fit | K13: Confirm Worldpay RM, processing scope and renewal dates; map enterprise technology owner and POS/payments decision window. | L13: Meeting-ready | M13: RBB ecosystem intelligence, 2026-09-30 | N13: Brand / chain | O13: Brand/system footprint from existing RBB research | P13: Medium | Q13: Unconfirmed — ask Worldpay | R13: Who at Worldpay owns this relationship, what merchant IDs/legal entities are in scope, and is coverage enterprise, franchisee, or a single site?
A14: A — Meeting focus | B14: Ben & Jerry'S | C14: Yes | D14: Dessert | E14: 363 | F14: 148 | H14: Technomic rank 363; ~148 units. Dessert account from Worldpay backbook. | I14: No non-Worldpay technology verified | J14: Source-marked synergy fit | K14: Confirm Worldpay RM, processing scope and renewal dates; map enterprise technology owner and POS/payments decision window. | L14: Meeting-ready | M14: RBB ecosystem intelligence, 2026-09-30 | N14: Brand / chain | O14: Brand/system footprint from existing RBB research | P14: Medium | Q14: Unconfirmed — ask Worldpay | R14: Who at Worldpay owns this relationship, what merchant IDs/legal entities are in scope, and is coverage enterprise, franchisee, or a single site?
A15: A — Meeting focus | B15: Honey Dew Donuts | C15: Yes | D15: Coffee / Bakery | E15: 577 | F15: 108 | H15: Technomic rank 577; ~108 units. Coffee account from Worldpay backbook. | I15: Loyalty: PAR Technology (Punchh) | J15: Source-marked synergy fit | K15: Confirm Worldpay RM, processing scope and renewal dates; map enterprise technology owner and POS/payments decision window. | L15: Meeting-ready | M15: RBB ecosystem intelligence, 2026-09-30 | N15: Brand / chain | O15: Brand/system footprint from existing RBB research | P15: Medium | Q15: Unconfirmed — ask Worldpay | R15: Who at Worldpay owns this relationship, what merchant IDs/legal entities are in scope, and is coverage enterprise, franchisee, or a single site?
A16: A — Meeting focus | B16: American Blue Ribbon Holdings | C16: Yes | D16: Restaurant Group / Platform | G16: Multi-brand operator | H16: Scale not yet verified. Family Dining account from Worldpay backbook. Platform/owner: Multi-brand operator. | I16: No non-Worldpay technology verified | J16: Source-marked synergy fit | K16: Confirm Worldpay RM, processing scope and renewal dates; map enterprise technology owner and POS/payments decision window. | L16: Partial | M16: RBB ecosystem intelligence, 2026-09-30 | N16: Restaurant group / platform | O16: WP merchant/entity footprint—not safe to infer from brand | P16: Needs WP confirmation | Q16: Unconfirmed — ask Worldpay | R16: Who at Worldpay owns this relationship, what merchant IDs/legal entities are in scope, and is coverage enterprise, franchisee, or a single site?
A17: A — Meeting focus | B17: Aurify Brands, Llc | C17: Yes | D17: Restaurant Group / Platform | G17: Multi-brand operator | H17: Scale not yet verified. Foodservice account from Worldpay backbook. Platform/owner: Multi-brand operator. | I17: No non-Worldpay technology verified | J17: Source-marked synergy fit | K17: Confirm Worldpay RM, processing scope and renewal dates; map enterprise technology owner and POS/payments decision window. | L17: Partial | M17: RBB ecosystem intelligence, 2026-09-30 | N17: Restaurant group / platform | O17: WP merchant/entity footprint—not safe to infer from brand | P17: Needs WP confirmation | Q17: Unconfirmed — ask Worldpay | R17: Who at Worldpay owns this relationship, what merchant IDs/legal entities are in scope, and is coverage enterprise, franchisee, or a single site?
A18: A — Meeting focus | B18: Caribou Coffee #1243 | C18: Yes | D18: Coffee & Beverage | F18: 800 | G18: JAB beverage platform | H18: Public footprint refreshed 2026-09-30; distinguish brand footprint from the exact WP merchant/entity scope. | I18: No non-Worldpay technology verified | J18: Source-marked synergy fit | K18: Confirm Worldpay RM, processing scope and renewal dates; map enterprise technology owner and POS/payments decision window. | L18: Public footprint refreshed; WP ownership open | M18: RBB ecosystem intelligence, 2026-09-30 | https://www.cariboucoffee.com/about-us/ | N18: Legal entity / franchisee / site record | O18: Global brand footprint; WP row may be one merchant/site | P18: Medium | Q18: Unconfirmed — ask Worldpay | R18: Who at Worldpay owns this relationship, what merchant IDs/legal entities are in scope, and is coverage enterprise, franchisee, or a single site?
A19: A — Meeting focus | B19: Carvel | C19: Yes | D19: Dessert / Ice Cream | F19: 374 | G19: GoTo Foods | H19: Public footprint refreshed 2026-09-30; distinguish brand footprint from the exact WP merchant/entity scope. | I19: No non-Worldpay technology verified | J19: Source-marked synergy fit | K19: Confirm Worldpay RM, processing scope and renewal dates; map enterprise technology owner and POS/payments decision window. | L19: Public footprint refreshed; WP ownership open | M19: RBB ecosystem intelligence, 2026-09-30 | https://development.gotofoods.com/wp-content/uploads/2025/03/GTF_Digital_IncentiveBrochure2025.pdf | https://locations.carvel.com/ | N19: Brand / chain | O19: U.S. brand footprint | P19: High | Q19: Unconfirmed — ask Worldpay | R19: Who at Worldpay owns this relationship, what merchant IDs/legal entities are in scope, and is coverage enterprise, franchisee, or a single site?
A20: A — Meeting focus | B20: Coffee Bean & Tea Leaf Ma | C20: Yes | D20: Coffee & Beverage | F20: 193 | G20: Jollibee Foods Corporation | H20: Public footprint refreshed 2026-09-30; distinguish brand footprint from the exact WP merchant/entity scope. | I20: No non-Worldpay technology verified | J20: Source-marked synergy fit | K20: Confirm Worldpay RM, processing scope and renewal dates; map enterprise technology owner and POS/payments decision window. | L20: Public footprint refreshed; WP ownership open | M20: RBB ecosystem intelligence, 2026-09-30 | https://www.coffeebean.com/store/index.html | N20: Brand / chain | O20: U.S. brand footprint | P20: High | Q20: Unconfirmed — ask Worldpay | R20: Who at Worldpay owns this relationship, what merchant IDs/legal entities are in scope, and is coverage enterprise, franchisee, or a single site?
A21: A — Meeting focus | B21: Jamba Juice | C21: Yes | D21: Juice / Smoothie | F21: 720 | G21: GoTo Foods | H21: Public footprint refreshed 2026-09-30; distinguish brand footprint from the exact WP merchant/entity scope. | I21: No non-Worldpay technology verified | J21: Source-marked synergy fit | K21: Confirm Worldpay RM, processing scope and renewal dates; map enterprise technology owner and POS/payments decision window. | L21: Public footprint refreshed; WP ownership open | M21: RBB ecosystem intelligence, 2026-09-30 | https://development.gotofoods.com/wp-content/uploads/2025/03/GTF_Digital_IncentiveBrochure2025.pdf | https://locations.jamba.com/ | N21: Brand / chain | O21: U.S. brand footprint | P21: High | Q21: Unconfirmed — ask Worldpay | R21: Who at Worldpay owns this relationship, what merchant IDs/legal entities are in scope, and is coverage enterprise, franchisee, or a single site?
A22: A — Meeting focus | B22: Peet'S Coffee & Tea | C22: Yes | D22: Coffee & Beverage | G22: JDE Peet's / JAB | H22: Scale not yet verified. Coffee account from Worldpay backbook. Platform/owner: JDE Peet's / JAB. | I22: No non-Worldpay technology verified | J22: Source-marked synergy fit | K22: Confirm Worldpay RM, processing scope and renewal dates; map enterprise technology owner and POS/payments decision window. | L22: Partial | M22: RBB ecosystem intelligence, 2026-09-30 | N22: Brand / chain | O22: Brand footprint not yet verified | P22: Needs research | Q22: Unconfirmed — ask Worldpay | R22: Who at Worldpay owns this relationship, what merchant IDs/legal entities are in scope, and is coverage enterprise, franchisee, or a single site?
A23: B — Qualify | B23: Shoneys | C23: Yes | D23: Family Dining | E23: 383 | F23: 57 | H23: Technomic rank 383; ~57 units. Family Dining account from Worldpay backbook. | I23: No non-Worldpay technology verified | J23: Source-marked synergy fit | K23: Validate corporate scale, buying authority, current POS/payments stack and whether the Worldpay relationship is enterprise or franchise-level. | L23: Meeting-ready | M23: RBB ecosystem intelligence, 2026-09-30 | N23: Brand / chain | O23: Brand/system footprint from existing RBB research | P23: Medium | Q23: Unconfirmed — ask Worldpay | R23: Who at Worldpay owns this relationship, what merchant IDs/legal entities are in scope, and is coverage enterprise, franchisee, or a single site?
A24: B — Qualify | B24: Fuddruckers | C24: Yes | D24: Fast Casual — Burger | E24: 505 | F24: 52 | H24: Technomic rank 505; ~52 units. Burger account from Worldpay backbook. | I24: back_office_operations: Crunchtime | J24: Source-marked synergy fit | K24: Validate corporate scale, buying authority, current POS/payments stack and whether the Worldpay relationship is enterprise or franchise-level. | L24: Meeting-ready | M24: RBB ecosystem intelligence, 2026-09-30 | N24: Brand / chain | O24: Brand/system footprint from existing RBB research | P24: Medium | Q24: Unconfirmed — ask Worldpay | R24: Who at Worldpay owns this relationship, what merchant IDs/legal entities are in scope, and is coverage enterprise, franchisee, or a single site?
A25: B — Qualify | B25: Gold Star Chili | C25: Yes | D25: QSR — Chili / Sandwich | E25: 517 | F25: 59 | H25: Technomic rank 517; ~59 units. Burger account from Worldpay backbook. | I25: POS: PAR Technology (Brink); pos: PAR Technology | J25: Source-marked synergy fit | K25: Validate corporate scale, buying authority, current POS/payments stack and whether the Worldpay relationship is enterprise or franchise-level. | L25: Meeting-ready | M25: RBB ecosystem intelligence, 2026-09-30 | N25: Brand / chain | O25: Brand/system footprint from existing RBB research | P25: Medium | Q25: Unconfirmed — ask Worldpay | R25: Who at Worldpay owns this relationship, what merchant IDs/legal entities are in scope, and is coverage enterprise, franchisee, or a single site?
A26: B — Qualify | B26: Scramblers | C26: Yes | D26: Family Dining / Breakfast | E26: 985 | F26: 28 | H26: Technomic rank 985; ~28 units. Family Dining account from Worldpay backbook. | I26: No non-Worldpay technology verified | J26: Source-marked synergy fit | K26: Validate corporate scale, buying authority, current POS/payments stack and whether the Worldpay relationship is enterprise or franchise-level. | L26: Partial | M26: RBB ecosystem intelligence, 2026-09-30 | N26: Brand / chain | O26: Brand/system footprint from existing RBB research | P26: Medium | Q26: Unconfirmed — ask Worldpay | R26: Who at Worldpay owns this relationship, what merchant IDs/legal entities are in scope, and is coverage enterprise, franchisee, or a single site?
A27: B — Qualify | B27: Bennigan'S | C27: Yes | D27: Casual Dining | E27: 1399 | F27: 6 | H27: Technomic rank 1399; ~6 units. Full-Service Dining account from Worldpay backbook. | I27: No non-Worldpay technology verified | J27: Source-marked synergy fit | K27: Validate corporate scale, buying authority, current POS/payments stack and whether the Worldpay relationship is enterprise or franchise-level. | L27: Partial | M27: RBB ecosystem intelligence, 2026-09-30 | N27: Brand / chain | O27: Brand/system footprint from existing RBB research | P27: Medium | Q27: Unconfirmed — ask Worldpay | R27: Who at Worldpay owns this relationship, what merchant IDs/legal entities are in scope, and is coverage enterprise, franchisee, or a single site?
A28: B — Qualify | B28: Tom & Chee | C28: Yes | D28: Fast Casual — Sandwich | E28: 1499 | F28: 7 | H28: Technomic rank 1499; ~7 units. Sandwich account from Worldpay backbook. | I28: No non-Worldpay technology verified | J28: Source-marked synergy fit | K28: Validate corporate scale, buying authority, current POS/payments stack and whether the Worldpay relationship is enterprise or franchise-level. | L28: Partial | M28: RBB ecosystem intelligence, 2026-09-30 | N28: Brand / chain | O28: Brand/system footprint from existing RBB research | P28: Medium | Q28: Unconfirmed — ask Worldpay | R28: Who at Worldpay owns this relationship, what merchant IDs/legal entities are in scope, and is coverage enterprise, franchisee, or a single site?
A29: B — Qualify | B29: Avi Foodsystems | C29: Yes | D29: Contract Foodservice | H29: Scale not yet verified. Foodservice account from Worldpay backbook. | I29: No non-Worldpay technology verified | J29: Source-marked synergy fit | K29: Validate corporate scale, buying authority, current POS/payments stack and whether the Worldpay relationship is enterprise or franchise-level. | L29: Partial | M29: RBB ecosystem intelligence, 2026-09-30 | N29: Brand / chain | O29: Brand footprint not yet verified | P29: Needs research | Q29: Unconfirmed — ask Worldpay | R29: Who at Worldpay owns this relationship, what merchant IDs/legal entities are in scope, and is coverage enterprise, franchisee, or a single site?
A30: B — Qualify | B30: Chateau Restaurant | C30: Yes | D30: Casual Dining — Italian | H30: Scale not yet verified. Full-Service Dining account from Worldpay backbook. | I30: No non-Worldpay technology verified | J30: Source-marked synergy fit | K30: Validate corporate scale, buying authority, current POS/payments stack and whether the Worldpay relationship is enterprise or franchise-level. | L30: Partial | M30: RBB ecosystem intelligence, 2026-09-30 | N30: Brand / chain | O30: Brand footprint not yet verified | P30: Needs research | Q30: Unconfirmed — ask Worldpay | R30: Who at Worldpay owns this relationship, what merchant IDs/legal entities are in scope, and is coverage enterprise, franchisee, or a single site?
A31: B — Qualify | B31: Cocula Restaurant | C31: Yes | D31: Casual Dining — Mexican | H31: Scale not yet verified. Mexican account from Worldpay backbook. | I31: No non-Worldpay technology verified | J31: Source-marked synergy fit | K31: Validate corporate scale, buying authority, current POS/payments stack and whether the Worldpay relationship is enterprise or franchise-level. | L31: Partial | M31: RBB ecosystem intelligence, 2026-09-30 | N31: Brand / chain | O31: Brand footprint not yet verified | P31: Needs research | Q31: Unconfirmed — ask Worldpay | R31: Who at Worldpay owns this relationship, what merchant IDs/legal entities are in scope, and is coverage enterprise, franchisee, or a single site?
A32: B — Qualify | B32: Creole Cuisine Restaurant | C32: Yes | D32: Restaurant Group / Platform | H32: Scale not yet verified. Full-Service Dining account from Worldpay backbook. | I32: No non-Worldpay technology verified | J32: Source-marked synergy fit | K32: Validate corporate scale, buying authority, current POS/payments stack and whether the Worldpay relationship is enterprise or franchise-level. | L32: Partial | M32: RBB ecosystem intelligence, 2026-09-30 | N32: Restaurant group / platform | O32: WP merchant/entity footprint—not safe to infer from brand | P32: Needs WP confirmation | Q32: Unconfirmed — ask Worldpay | R32: Who at Worldpay owns this relationship, what merchant IDs/legal entities are in scope, and is coverage enterprise, franchisee, or a single site?
A33: B — Qualify | B33: Cyclone Anaya | C33: Yes | D33: Casual Dining — Mexican | H33: Scale not yet verified. Mexican account from Worldpay backbook. | I33: No non-Worldpay technology verified | J33: Source-marked synergy fit | K33: Validate corporate scale, buying authority, current POS/payments stack and whether the Worldpay relationship is enterprise or franchise-level. | L33: Partial | M33: RBB ecosystem intelligence, 2026-09-30 | N33: Brand / chain | O33: Brand footprint not yet verified | P33: Needs research | Q33: Unconfirmed — ask Worldpay | R33: Who at Worldpay owns this relationship, what merchant IDs/legal entities are in scope, and is coverage enterprise, franchisee, or a single site?
A34: B — Qualify | B34: David'S Pizza | C34: Yes | D34: Pizza | H34: Scale not yet verified. Pizza account from Worldpay backbook. | I34: No non-Worldpay technology verified | J34: Source-marked synergy fit | K34: Validate corporate scale, buying authority, current POS/payments stack and whether the Worldpay relationship is enterprise or franchise-level. | L34: Partial | M34: RBB ecosystem intelligence, 2026-09-30 | N34: Brand / chain | O34: Brand footprint not yet verified | P34: Needs research | Q34: Unconfirmed — ask Worldpay | R34: Who at Worldpay owns this relationship, what merchant IDs/legal entities are in scope, and is coverage enterprise, franchisee, or a single site?
A35: B — Qualify | B35: Dibella'S | C35: Yes | D35: Fast Casual — Sandwich | H35: Scale not yet verified. Sandwich account from Worldpay backbook. | I35: No non-Worldpay technology verified | J35: Source-marked synergy fit | K35: Validate corporate scale, buying authority, current POS/payments stack and whether the Worldpay relationship is enterprise or franchise-level. | L35: Entity validation needed | M35: RBB ecosystem intelligence, 2026-09-30 | N35: Brand / chain | O35: Brand footprint not yet verified | P35: Needs research | Q35: Unconfirmed — ask Worldpay | R35: Who at Worldpay owns this relationship, what merchant IDs/legal entities are in scope, and is coverage enterprise, franchisee, or a single site?
A36: B — Qualify | B36: Famous Dave'S Bbq | C36: Yes | D36: Casual Dining — Barbecue | H36: Scale not yet verified. Barbecue account from Worldpay backbook. | I36: No non-Worldpay technology verified | J36: Source-marked synergy fit | K36: Validate corporate scale, buying authority, current POS/payments stack and whether the Worldpay relationship is enterprise or franchise-level. | L36: Partial | M36: RBB ecosystem intelligence, 2026-09-30 | N36: Brand / chain | O36: Brand footprint not yet verified | P36: Needs research | Q36: Unconfirmed — ask Worldpay | R36: Who at Worldpay owns this relationship, what merchant IDs/legal entities are in scope, and is coverage enterprise, franchisee, or a single site?
A37: B — Qualify | B37: Frischs | C37: Yes | D37: Family Dining / Burger | H37: Scale not yet verified. Family Dining account from Worldpay backbook. | I37: No non-Worldpay technology verified | J37: Source-marked synergy fit | K37: Validate corporate scale, buying authority, current POS/payments stack and whether the Worldpay relationship is enterprise or franchise-level. | L37: Partial | M37: RBB ecosystem intelligence, 2026-09-30 | N37: Brand / chain | O37: Brand footprint not yet verified | P37: Needs research | Q37: Unconfirmed — ask Worldpay | R37: Who at Worldpay owns this relationship, what merchant IDs/legal entities are in scope, and is coverage enterprise, franchisee, or a single site?
A38: B — Qualify | B38: Hungry Howies | C38: Yes | D38: Pizza | F38: 500 | H38: Public footprint refreshed 2026-09-30; distinguish brand footprint from the exact WP merchant/entity scope. | I38: No non-Worldpay technology verified | J38: Source-marked synergy fit | K38: Validate corporate scale, buying authority, current POS/payments stack and whether the Worldpay relationship is enterprise or franchise-level. | L38: Public footprint refreshed; WP ownership open | M38: RBB ecosystem intelligence, 2026-09-30 | https://hungryhowies.com/about-us | N38: Brand / chain | O38: Approximate U.S. brand footprint | P38: High | Q38: Unconfirmed — ask Worldpay | R38: Who at Worldpay owns this relationship, what merchant IDs/legal entities are in scope, and is coverage enterprise, franchisee, or a single site?
A39: B — Qualify | B39: Hwy 55 Burgers Shakes & F | C39: Yes | D39: Fast Casual — Burger | H39: Scale not yet verified. Burger account from Worldpay backbook. | I39: No non-Worldpay technology verified | J39: Source-marked synergy fit | K39: Validate corporate scale, buying authority, current POS/payments stack and whether the Worldpay relationship is enterprise or franchise-level. | L39: Partial | M39: RBB ecosystem intelligence, 2026-09-30 | N39: Brand / chain | O39: Brand footprint not yet verified | P39: Needs research | Q39: Unconfirmed — ask Worldpay | R39: Who at Worldpay owns this relationship, what merchant IDs/legal entities are in scope, and is coverage enterprise, franchisee, or a single site?
A40: B — Qualify | B40: Jake N Joes | C40: Yes | D40: Casual Dining — Sports Bar | H40: Scale not yet verified. Full-Service Dining account from Worldpay backbook. | I40: No non-Worldpay technology verified | J40: Source-marked synergy fit | K40: Validate corporate scale, buying authority, current POS/payments stack and whether the Worldpay relationship is enterprise or franchise-level. | L40: Partial | M40: RBB ecosystem intelligence, 2026-09-30 | N40: Brand / chain | O40: Brand footprint not yet verified | P40: Needs research | Q40: Unconfirmed — ask Worldpay | R40: Who at Worldpay owns this relationship, what merchant IDs/legal entities are in scope, and is coverage enterprise, franchisee, or a single site?
A41: B — Qualify | B41: Jeff Ruby | C41: Yes | D41: Fine Dining — Steakhouse | H41: Scale not yet verified. Steakhouse account from Worldpay backbook. | I41: No non-Worldpay technology verified | J41: Source-marked synergy fit | K41: Validate corporate scale, buying authority, current POS/payments stack and whether the Worldpay relationship is enterprise or franchise-level. | L41: Partial | M41: RBB ecosystem intelligence, 2026-09-30 | N41: Brand / chain | O41: Brand footprint not yet verified | P41: Needs research | Q41: Unconfirmed — ask Worldpay | R41: Who at Worldpay owns this relationship, what merchant IDs/legal entities are in scope, and is coverage enterprise, franchisee, or a single site?
...

Sheet Ranked Portfolio
A1: Ranked Worldpay Opportunity Portfolio — 2026-09-04 Master Plan
A2: Existing scored accounts preserved. 85 supplemental Worldpay ABM targets appended unranked on 2026-09-28 pending qualification.
A4: Rank | B4: Priority | C4: Account | D4: RM | E4: Tier | F4: Locations | G4: Score | H4: Strategic Value | I4: Active Trigger | J4: Access | K4: Lifecycle | L4: Deployment Health | M4: Whitespace | N4: Coordination | O4: Trigger / Current State | P4: Lifecycle Posture | Q4: Health | R4: Opportunity Type | S4: Immediate Next Action | T4: Key Vendors | U4: Field Intelligence | V4: Evidence Confidence | W4: Region | X4: Geo | Y4: Sub-segment | Z4: Relevant to synergy | AA4: Dyssynergy with WP | AB4: WP Attrition | AC4: WP Rep | AD4: WP Products Used | AE4: Genius Rep | AF4: GP Products Used | AG4: Supplemental Source | AH4: Account Type | AI4: Location Scope | AJ4: Location Confidence | AK4: WP Relationship Owner | AL4: Internal Clarification Needed
A5: 1 | B5: P1 | C5: DEL TACO LLC | D5: Maggie Lenhart | E5: Tier 2 | F5: 537 | G5: =(H5/5*'Scoring Model'!$B$5+I5/5*'Scoring Model'!$B$6+J5/5*'Scoring Model'!$B$7+K5/5*'Scoring Model'!$B$8+L5/5*'Scoring Model'!$B$9+M5/5*'Scoring Model'!$B$10+N5/5*'Scoring Model'!$B$11)*100 -> 83 | H5: 4 | I5: 5 | J5: 4 | K5: 4 | L5: 3 | M5: 4 | N5: 5 | O5: Worldpay extension active; Yadav acquisition creates a verified ownership-change window; sourcing event unconfirmed | P5: Aging NCR estate; post-acquisition multi-brand governance | Q5: Active relationship; technology and synergy timing to verify | R5: POS/payments + multi-brand consolidation | S5: Complete the extension, consolidate all GP leads, map Yadav technology governance and confirm any sourcing or vendor-consolidation event. | T5: NCR; NCR Connected Payments; Olo; Olo Pay; Bite | U5: Yadav Enterprises completed the acquisition in Dec. 2025. Direct CIO access and the extension remain strong; cost/stack review is a hypothesis pending customer confirmation. | V5: High RM intelligence + verified ownership event
A6: 2 | B6: P1 | C6: FIVE GUYS | D6: Avery Churchwell | E6: Tier 1 | F6: 1500 | G6: =(H6/5*'Scoring Model'!$B$5+I6/5*'Scoring Model'!$B$6+J6/5*'Scoring Model'!$B$7+K6/5*'Scoring Model'!$B$8+L6/5*'Scoring Model'!$B$9+M6/5*'Scoring Model'!$B$10+N6/5*'Scoring Model'!$B$11)*100 -> 82 | H6: 5 | I6: 5 | J6: 4 | K6: 5 | L6: 2 | M6: 2 | N6: 5 | O6: MJ Worsham remains the key influential contact. Multiple uncoordinated Genius outreach attempts have created account-ownership friction; MJ and Zerick were invited to the FSTEC happy hour but had not responded as of the September 4 Avery call. No formal RFI/RFP is confirmed. | P6: Mature U.S. PAR estate; global support gaps and modularity hypothesis | Q6: No verified failure; renewal dates and evaluation type require confirmation | R6: Pre-RFP shaping + transaction-metered POS feasibility | S6: Centralize all Five Guys outreach through Todd and Avery; avoid generic prospecting. Use FSTEC only for a relationship-first conversation, validate whether MJ still engages former PAR account manager Chad Kaisel, and confirm PAR term, evaluation type, sponsor, scope and global gaps before presenting any commercial model. | T6: PAR Brink; NCR (EMEA); CrunchTime; Olo; Worldpay/Global Payments; Verifone; LineTen | U6: Avery reported that her merchant questioned why multiple Genius people were contacting Five Guys without her knowledge. She emphasized that introductions should flow through the relationship owner. MJ is resistant to consolidating multiple lines of business with one vendor and will require a compelling reason to engage. Todd is internally exploring a capped per-card-swipe technology funding model, but it is not approved or customer-presented. | V6: High RM intelligence dated 2026-09-04 / buying event, dates and commercial model remain unconfirmed
A7: 3 | B7: P1 | C7: Focus Brands (GoTo Foods) | D7: Brian Wood | E7: Tier 2 | F7: 2600 | G7: =(H7/5*'Scoring Model'!$B$5+I7/5*'Scoring Model'!$B$6+J7/5*'Scoring Model'!$B$7+K7/5*'Scoring Model'!$B$8+L7/5*'Scoring Model'!$B$9+M7/5*'Scoring Model'!$B$10+N7/5*'Scoring Model'!$B$11)*100 -> 81 | H7: 5 | I7: 5 | J7: 3 | K7: 2 | L7: 5 | M7: 4 | N7: 4 | O7: Qu established; DMB relationship development and defense against Qu Pay/platform expansion | P7: Deploying since 2024 | Q7: Schedule risk reported | R7: DMB-led adjacency + payments defense | S7: Map DMB/CMS and buying center; quantify uncovered adjacencies and defend payments without positioning a near-term POS displacement. | T7: Qu; FreedomPay; Olo; Monkey Media | U7: Qu remains established. Treat PAR/Qu-style platform consolidation and native-payments attachment as the competitive pattern to counter. | V7: High RM intelligence + public evidence
A8: 4 | B8: P1 | C8: SUBWAY | D8: Stacie Davis | E8: Tier 1 | F8: 20000 | G8: =(H8/5*'Scoring Model'!$B$5+I8/5*'Scoring Model'!$B$6+J8/5*'Scoring Model'!$B$7+K8/5*'Scoring Model'!$B$8+L8/5*'Scoring Model'!$B$9+M8/5*'Scoring Model'!$B$10+N8/5*'Scoring Model'!$B$11)*100 -> 79 | H8: 5 | I8: 4 | J8: 4 | K8: 3 | L8: 3 | M8: 4 | N8: 4 | O8: Proprietary POS; internal report indicates a global Genius KDS deployment, replacing the prior DMB assumption | P8: Fragmented global/franchise estate; existing Genius relationship requires verification | Q8: Product, site coverage, ownership and commitments unresolved | R8: Existing Genius KDS scope verification + relationship map | S8: Confirm the Genius product owner, KDS sites, deployment status, commitments and customer sponsor before proposing any additional adjacency. | T8: Proprietary; FreedomPay; Ingenico; Genius KDS (reported internally, unverified) | U8: Ryan Hildebrand described proprietary POS plus a global Genius KDS deployment. Reconcile that internal view with prior DMB reporting. | V8: High internal intelligence / exact scope unresolved
A9: 5 | B9: P2 | C9: THE STEAK N SHAKE CO | D9: Maggie Lenhart | E9: Tier 2 | F9: 550 | G9: =(H9/5*'Scoring Model'!$B$5+I9/5*'Scoring Model'!$B$6+J9/5*'Scoring Model'!$B$7+K9/5*'Scoring Model'!$B$8+L9/5*'Scoring Model'!$B$9+M9/5*'Scoring Model'!$B$10+N9/5*'Scoring Model'!$B$11)*100 -> 76 | H9: 4 | I9: 4 | J9: 3 | K9: 4 | L9: 4 | M9: 4 | N9: 3 | O9: Kiosk transition and NCR reporting integration problems | P9: Transitioning adjacent stack | Q9: Current implementation pain | R9: Kiosk integration recovery + digital adjacency | S9: Name the kiosk vendor and owners; document certification, NCR reporting and mobile-app issues with dated remediation milestones. | T9: NCR; NCR Connected Payments; QikServe; Olo; NovaDine | U9: Maggie reports a difficult kiosk-vendor transition and integration/reporting issues with NCR. | V9: High RM intelligence
A10: 6 | B10: P2 | C10: CHOICE HOTELS | D10: Brian Wood | E10: Tier 2 | G10: =(H10/5*'Scoring Model'!$B$5+I10/5*'Scoring Model'!$B$6+J10/5*'Scoring Model'!$B$7+K10/5*'Scoring Model'!$B$8+L10/5*'Scoring Model'!$B$9+M10/5*'Scoring Model'!$B$10+N10/5*'Scoring Model'!$B$11)*100 -> 75 | H10: 3 | I10: 5 | J10: 3 | K10: 4 | L10: 4 | M10: 3 | N10: 5 | O10: Gateway/acquiring RFP was active in July; current stage and deadlines now require refresh | P10: Deconverting | Q10: Shift4 performance concern reported | R10: Payments win-back + hospitality adjacency | S10: Confirm whether the RFP remains active, current stage, decision dates, retained Worldpay estate, sponsor and restaurant/DMB scope. | T10: Shift4 | U10: Brian and Brendan report an active RFP, remaining Worldpay locations and a possible full win-back. | V10: High RM intelligence / status aging
A11: 7 | B11: P2 | C11: RDS FIVE-UNIT REBRAND PILOT | D11: RDS / Darren Heinze | E11: Channel pilot | F11: 5 | G11: =(H11/5*'Scoring Model'!$B$5+I11/5*'Scoring Model'!$B$6+J11/5*'Scoring Model'!$B$7+K11/5*'Scoring Model'!$B$8+L11/5*'Scoring Model'!$B$9+M11/5*'Scoring Model'!$B$10+N11/5*'Scoring Model'!$B$11)*100 -> 74 | H11: 2 | I11: 4 | J11: 4 | K11: 4 | L11: 3 | M11: 5 | N11: 5 | O11: Five former Taco Cabana locations are rebranding and evaluating a clean-slate stack and digital menu boards | P11: Clean-slate conversion; opening and conversion dates unconfirmed | Q11: High channel access; commercial, support and account-protection model not yet defined | R11: RDS-led Genius pilot and reseller proof | S11: Confirm entity/concept, authority, dates, budget and incumbent contracts; define scope, economics, support, success metrics and case-study rights before Genius World. | T11: To be determined: Genius POS/payments; DMB; drive-thru; loyalty; back office; hardware | U11: RDS is authorized to resell Genius but lacks implementation experience. The pilot can create channel proof before any larger protected-account motion. | V11: High field confidence / customer facts require documentation
A12: 8 | B12: P2 | C12: POLLO CAMPERO | D12: Unassigned / Worldpay | E12: Emerging strategic | F12: 150 | G12: =(H12/5*'Scoring Model'!$B$5+I12/5*'Scoring Model'!$B$6+J12/5*'Scoring Model'!$B$7+K12/5*'Scoring Model'!$B$8+L12/5*'Scoring Model'!$B$9+M12/5*'Scoring Model'!$B$10+N12/5*'Scoring Model'!$B$11)*100 -> 72 | H12: 4 | I12: 4 | J12: 3 | K12: 3 | L12: 3 | M12: 4 | N12: 4 | O12: Potential RFI and DMB dissatisfaction; Oracle migration and referral status require immediate qualification | P12: Mixed NCR/Oracle estate; international platform decision may be underway | Q12: Decision openness, scope, deadlines and sponsor unconfirmed | R12: RFI qualification + international platform/payments/DMB | S12: Obtain NDA/RFI, confirm sponsor and deadlines, separate the stalled referral from the procurement stream, and apply country-by-country bid/no-bid gates. | T12: Oracle Simphony; NCR Aloha; Fiserv; Olo Pay/Stripe; Valutec; DMB incumbent unverified | U12: Split estate, reported $200M+ card volume and international footprint create strategic fit, but the Oracle decision may already be advanced. | V12: Strong internal brief / customer procurement not confirmed
A13: 9 | B13: P3 | C13: EAT'N PARK HOSPITALITY GRP INC | D13: Avery Churchwell | E13: Tier 2 | F13: 137 | G13: =(H13/5*'Scoring Model'!$B$5+I13/5*'Scoring Model'!$B$6+J13/5*'Scoring Model'!$B$7+K13/5*'Scoring Model'!$B$8+L13/5*'Scoring Model'!$B$9+M13/5*'Scoring Model'!$B$10+N13/5*'Scoring Model'!$B$11)*100 -> 64 | H13: 3 | I13: 3 | J13: 2 | K13: 3 | L13: 3 | M13: 5 | N13: 4 | O13: Multi-concept conversion noted by Worldpay | P13: Mixed / transitioning | Q13: Unknown | R13: Consolidation and payments | S13: Separate stacks by concept and validate Oracle/FreedomPay/Tillster/Olo/Nextep ownership. | T13: Oracle Simphony; FreedomPay; Tillster; Olo; Nextep | V13: Internal baseline only
A14: 10 | B14: P3 | C14: FREDDY'S FROZEN CUSTARD LLC | D14: Avery Churchwell | E14: Tier 2 | F14: 500 | G14: =(H14/5*'Scoring Model'!$B$5+I14/5*'Scoring Model'!$B$6+J14/5*'Scoring Model'!$B$7+K14/5*'Scoring Model'!$B$8+L14/5*'Scoring Model'!$B$9+M14/5*'Scoring Model'!$B$10+N14/5*'Scoring Model'!$B$11)*100 -> 63 | H14: 4 | I14: 3 | J14: 4 | K14: 1 | L14: 3 | M14: 3 | N14: 5 | O14: Protected RDS account with no verified displacement event. Avery invited Freddy's contacts to the FSTEC happy hour but had received no response as of September 4. | P14: Established PAR via RDS; protected channel relationship | Q14: No verified displacement event; RDS has deep operational and CFO access | R14: RDS-led value review and modular watchlist | S14: Keep all activity RDS-led. Confirm whether RDS connected with Ryan after Genius World, identify any FSTEC attendance, and wait for a customer-defined business problem before advancing a value case. | T14: PAR Brink via RDS; Olo Pay; Creative Realities DMB; Neon entry reported, unverified | U14: Avery and Todd agreed that RDS is the strongest coordinated route into Freddy's. Todd had previously discussed Genius with RDS at the Freddy's show; an RDS contact attended Genius World, but follow-through with Ryan still needed confirmation. | V14: High RM/channel intelligence dated 2026-09-04 / no active customer buying trigger verified
A15: 11 | B15: P3 | C15: PAPA JOHN'S USA, INC. | D15: Brian Wood | E15: Tier 1 | F15: 3300 | G15: =(H15/5*'Scoring Model'!$B$5+I15/5*'Scoring Model'!$B$6+J15/5*'Scoring Model'!$B$7+K15/5*'Scoring Model'!$B$8+L15/5*'Scoring Model'!$B$9+M15/5*'Scoring Model'!$B$10+N15/5*'Scoring Model'!$B$11)*100 -> 62 | H15: 5 | I15: 3 | J15: 3 | K15: 1 | L15: 2 | M15: 4 | N15: 2 | O15: PAR POS + OPS implementation begins in 2026; rollout through 2027; Linux-build dependency reported but unverified | P15: Newly selected / deploying | Q15: PAR reports milestones on track; watch implementation and technical dependencies | R15: DMB adjacency + implementation-risk watch | S15: Map DMB and adjacent owners; monitor implementation milestones and validate the reported Linux-build dependency without positioning POS displacement. | T15: PAR POS; PAR OPS; legacy Mainstreet Monetra; Ingenico | U15: PAR publicly reports development progress and implementation later in 2026. The Linux requirement is confidential field intelligence requiring technical validation. | V15: High public evidence + unverified technical-risk lead
A16: 12 | B16: P3 | C16: CRACKER BARREL OLD COUNTRY STORE, INC. | D16: Brian Wood | E16: Tier 2 | F16: 600 | G16: =(H16/5*'Scoring Model'!$B$5+I16/5*'Scoring Model'!$B$6+J16/5*'Scoring Model'!$B$7+K16/5*'Scoring Model'!$B$8+L16/5*'Scoring Model'!$B$9+M16/5*'Scoring Model'!$B$10+N16/5*'Scoring Model'!$B$11)*100 -> 61 | H16: 4 | I16: 3 | J16: 3 | K16: 2 | L16: 3 | M16: 3 | N16: 3 | O16: Oracle Simphony rollout continuing in 2026 | P16: Deploying / transition | Q16: Early field adoption signals; verify | R16: Adjacent stack and deployment support | S16: Confirm rollout completion, FreedomPay scope, operational issues and remaining adjacent gaps. | T16: Oracle Simphony; FreedomPay; Olo | V16: Mixed / see ledger
A17: 13 | B17: P3 | C17: MILLLER'S ALE HOUSE | D17: Avery Churchwell | E17: Tier 2 | F17: 112 | G17: =(H17/5*'Scoring Model'!$B$5+I17/5*'Scoring Model'!$B$6+J17/5*'Scoring Model'!$B$7+K17/5*'Scoring Model'!$B$8+L17/5*'Scoring Model'!$B$9+M17/5*'Scoring Model'!$B$10+N17/5*'Scoring Model'!$B$11)*100 -> 61 | H17: 3 | I17: 3 | J17: 2 | K17: 4 | L17: 3 | M17: 3 | N17: 4 | O17: Digital payments moved direct to Olo | P17: Established POS; recent digital payment change | Q17: Unknown | R17: In-store POS/payments and guest experience | S17: Confirm lost scope, NCR renewal, Ziosk footprint and remaining payments opportunity. | T17: NCR; Ziosk; Olo Pay | V17: Internal baseline only
A18: 14 | B18: P3 | C18: LAROSA'S INC | D18: Maggie Lenhart | E18: Tier 2 | F18: 76 | G18: =(H18/5*'Scoring Model'!$B$5+I18/5*'Scoring Model'!$B$6+J18/5*'Scoring Model'!$B$7+K18/5*'Scoring Model'!$B$8+L18/5*'Scoring Model'!$B$9+M18/5*'Scoring Model'!$B$10+N18/5*'Scoring Model'!$B$11)*100 -> 59 | H18: 2 | I18: 3 | J18: 2 | K18: 4 | L18: 3 | M18: 4 | N18: 3 | O18: Possible EMV modernization gap | P18: Mature / niche POS | Q18: Unknown | R18: EMV, payments and enterprise modernization | S18: Validate POS.Cloud contract, non-EMV exposure, franchise scope and replacement appetite. | T18: Point of Sale.Cloud; Mainstreet Monetra; triPOS | V18: Internal baseline only
A19: 15 | B19: P3 | C19: CHURCHS CHICKEN 558 | D19: Maggie Lenhart | E19: Tier 2 | F19: 832 | G19: =(H19/5*'Scoring Model'!$B$5+I19/5*'Scoring Model'!$B$6+J19/5*'Scoring Model'!$B$7+K19/5*'Scoring Model'!$B$8+L19/5*'Scoring Model'!$B$9+M19/5*'Scoring Model'!$B$10+N19/5*'Scoring Model'!$B$11)*100 -> 58 | H19: 4 | I19: 2 | J19: 2 | K19: 3 | L19: 2 | M19: 4 | N19: 3 | O19: Qu vs Oracle decision not officially communicated to Worldpay | P19: Established | Q19: Decision believed to favor Qu; verify | R19: DMB/drive-thru adjacency after POS verification | S19: Use Maggie to confirm the final POS decision and current payments integration before positioning an adjacency. | T19: Qu; Aurus; Olo; Bite | U19: Maggie reports Qu is assumed but not officially confirmed; leadership changes delayed clarity. | V19: High RM intelligence / unresolved
A20: 16 | B20: P3 | C20: GOLDEN CORRAL | D20: Maggie Lenhart | E20: Tier 2 | F20: 640 | G20: =(H20/5*'Scoring Model'!$B$5+I20/5*'Scoring Model'!$B$6+J20/5*'Scoring Model'!$B$7+K20/5*'Scoring Model'!$B$8+L20/5*'Scoring Model'!$B$9+M20/5*'Scoring Model'!$B$10+N20/5*'Scoring Model'!$B$11)*100 -> 58 | H20: 4 | I20: 2 | J20: 2 | K20: 3 | L20: 2 | M20: 4 | N20: 3 | O20: No dated public trigger found | P20: Established / date unknown | Q20: Unknown | R20: Franchise payments + adjacent discovery | S20: Verify Qu start date, Aurus/Olo scopes, franchise penetration and contract dates. | T20: Qu; Aurus; Olo | V20: Internal baseline only
A21: 17 | B21: P3 | C21: Red Robin | D21: Avery Churchwell | E21: Tier 2 | F21: 500 | G21: =(H21/5*'Scoring Model'!$B$5+I21/5*'Scoring Model'!$B$6+J21/5*'Scoring Model'!$B$7+K21/5*'Scoring Model'!$B$8+L21/5*'Scoring Model'!$B$9+M21/5*'Scoring Model'!$B$10+N21/5*'Scoring Model'!$B$11)*100 -> 58 | H21: 4 | I21: 2 | J21: 2 | K21: 4 | L21: 2 | M21: 3 | N21: 3 | O21: Avery sees signs that Red Robin may be in a better operating position and considers it a renewed prospecting possibility; no customer-confirmed buying event was disclosed. | P21: Mature mixed stack | Q21: Customer pressure; limited capital | R21: Pay-at-table replacement + payment savings | S21: Validate the improved-business-condition signal with current public results and direct RM knowledge, then confirm NCR term, Ziosk dissatisfaction, decision ownership and whether a pay-at-table/payment-savings discussion is timely. | T21: NCR Aloha; Ziosk; Olo; Monkey Media | U21: On September 4 Avery said recent reading suggested Red Robin was in a better spot and should be reconsidered as a possibility. This is a directional RM assessment, not a confirmed customer initiative. | V21: Medium RM assessment dated 2026-09-04 / customer trigger unverified
A22: 18 | B22: P3 | C22: BOB EVANS RESTAURANTS, LLC | D22: Brian Wood | E22: Tier 2 | F22: 450 | G22: =(H22/5*'Scoring Model'!$B$5+I22/5*'Scoring Model'!$B$6+J22/5*'Scoring Model'!$B$7+K22/5*'Scoring Model'!$B$8+L22/5*'Scoring Model'!$B$9+M22/5*'Scoring Model'!$B$10+N22/5*'Scoring Model'!$B$11)*100 -> 57 | H22: 3 | I22: 2 | J22: 2 | K22: 4 | L22: 2 | M22: 4 | N22: 3 | O22: No dated primary-source trigger verified | P22: Established NCR estate | Q22: Unknown | R22: Aging POS and adjacent modernization | S22: Confirm earliest Aloha deployment/renewal and Connected Payments term. | T22: NCR Aloha; NCR Connected Payments | V22: Internal baseline only
A23: 19 | B23: P3 | C23: GRAETERS | D23: Maggie Lenhart | E23: Tier 2 | F23: 67 | G23: =(H23/5*'Scoring Model'!$B$5+I23/5*'Scoring Model'!$B$6+J23/5*'Scoring Model'!$B$7+K23/5*'Scoring Model'!$B$8+L23/5*'Scoring Model'!$B$9+M23/5*'Scoring Model'!$B$10+N23/5*'Scoring Model'!$B$11)*100 -> 57 | H23: 2 | I23: 3 | J23: 3 | K23: 3 | L23: 2 | M23: 4 | N23: 3 | O23: Product segmentation clarified | P23: PAR non-enterprise deployment | Q23: No adverse signal | R23: Enterprise upgrade or adjacent stack | S23: Confirm PAR product/SKU, reseller, site coverage and enterprise gaps; test migration economics without misclassifying current state. | T23: PAR Brink (non-enterprise); Olo | U23: Graeter's is a PAR customer but not PAR Enterprise. | V23: Mixed / see ledger
A24: 20 | B24: P3 | C24: STARBUCKS CORPORATION | D24: Stacie Davis | E24: Tier 1 | F24: 10000 | G24: =(H24/5*'Scoring Model'!$B$5+I24/5*'Scoring Model'!$B$6+J24/5*'Scoring Model'!$B$7+K24/5*'Scoring Model'!$B$8+L24/5*'Scoring Model'!$B$9+M24/5*'Scoring Model'!$B$10+N24/5*'Scoring Model'!$B$11)*100 -> 57 | H24: 5 | I24: 2 | J24: 2 | K24: 2 | L24: 2 | M24: 3 | N24: 4 | O24: Only partial Worldpay volume reported | P24: Proprietary / mature | Q24: Unknown | R24: Payments share expansion and hardware | S24: Quantify the 20% Worldpay footprint, renewal dates, licensed-store scope and Verifone lifecycle. | T24: Proprietary/VF PWC; Verifone | V24: Internal baseline only
A25: 21 | B25: P3 | C25: LITTLE CAESARS ENTERPRISE INC | D25: Avery Churchwell | E25: Tier 1 | F25: 4200 | G25: =(H25/5*'Scoring Model'!$B$5+I25/5*'Scoring Model'!$B$6+J25/5*'Scoring Model'!$B$7+K25/5*'Scoring Model'!$B$8+L25/5*'Scoring Model'!$B$9+M25/5*'Scoring Model'!$B$10+N25/5*'Scoring Model'!$B$11)*100 -> 56 | H25: 5 | I25: 2 | J25: 2 | K25: 1 | L25: 2 | M25: 4 | N25: 3 | O25: Relationship is active enough for technical-support interaction, but commercial follow-up is stalled: Avery reported three open items and no response to repeated emails for roughly a week and a half. | P25: Proprietary / entrenched | Q25: Unknown | R25: Payments, DMB, franchise and data adjacency | S25: Use the existing technical-support interaction to re-establish responsiveness, consolidate the three outstanding requests into one owner/action list, and map CaesarVision, payments renewal, DMB and franchise exceptions without leading with generic POS displacement. | T25: CaesarVision; Verifone; Mashgin | U25: Avery reported three items awaiting follow-up and no response to emails for approximately 1.5 weeks, despite participating in a technical-support call with the account earlier that week. | V25: High RM interaction evidence dated 2026-09-04 / commercial trigger unverified
A26: 22 | B26: P3 | C26: BLACK BEAR DINER | D26: Avery Churchwell | E26: Tier 2 | F26: 217 | G26: =(H26/5*'Scoring Model'!$B$5+I26/5*'Scoring Model'!$B$6+J26/5*'Scoring Model'!$B$7+K26/5*'Scoring Model'!$B$8+L26/5*'Scoring Model'!$B$9+M26/5*'Scoring Model'!$B$10+N26/5*'Scoring Model'!$B$11)*100 -> 55 | H26: 3 | I26: 3 | J26: 2 | K26: 2 | L26: 3 | M26: 3 | N26: 4 | O26: Transitioned toward Toast; Olo catering evidence | P26: Recently changed / deploying | Q26: Unknown | R26: Retain payments + adjacent gaps | S26: Confirm Toast deployment scope and whether Worldpay became unmanaged; map Olo modules and remaining corporate/franchise gaps. | T26: Toast; Olo | V26: Mixed / see ledger
A27: 23 | B27: P3 | C27: DOMINO'S PIZZA | D27: Stacie Davis | E27: Tier 1 | F27: 7000 | G27: =(H27/5*'Scoring Model'!$B$5+I27/5*'Scoring Model'!$B$6+J27/5*'Scoring Model'!$B$7+K27/5*'Scoring Model'!$B$8+L27/5*'Scoring Model'!$B$9+M27/5*'Scoring Model'!$B$10+N27/5*'Scoring Model'!$B$11)*100 -> 53 | H27: 5 | I27: 2 | J27: 2 | K27: 1 | L27: 2 | M27: 3 | N27: 3 | O27: Proprietary estate; no open trigger verified | P27: Proprietary / entrenched | Q27: Unknown | R27: Payments, hardware and franchise adjacency | S27: Confirm ACI/Cybersource tenure, processor split and franchise technology control. | T27: Proprietary; ACI/Cybersource; Ingenico | V27: Internal baseline only
A28: 24 | B28: P3 | C28: FIREHOUSE RESTAURANT | D28: Brian Wood | E28: Tier 2 | F28: 1200 | G28: =(H28/5*'Scoring Model'!$B$5+I28/5*'Scoring Model'!$B$6+J28/5*'Scoring Model'!$B$7+K28/5*'Scoring Model'!$B$8+L28/5*'Scoring Model'!$B$9+M28/5*'Scoring Model'!$B$10+N28/5*'Scoring Model'!$B$11)*100 -> 52 | H28: 4 | I28: 2 | J28: 2 | K28: 2 | L28: 2 | M28: 3 | N28: 3 | O28: Toast relationship appears strategic | P28: Established / strategic | Q28: No adverse signal | R28: Franchise payments and adjacent whitespace | S28: Confirm Toast modules and RBI governance; focus only on uncovered layers/franchise exceptions. | T28: Toast; eGiftify | V28: Internal baseline only
A29: 25 | B29: P3 | C29: BOYNE USA INC | D29: Avery Churchwell | E29: Tier 2 | F29: 17 | G29: =(H29/5*'Scoring Model'!$B$5+I29/5*'Scoring Model'!$B$6+J29/5*'Scoring Model'!$B$7+K29/5*'Scoring Model'!$B$8+L29/5*'Scoring Model'!$B$9+M29/5*'Scoring Model'!$B$10+N29/5*'Scoring Model'!$B$11)*100 -> 50 | H29: 2 | I29: 2 | J29: 2 | K29: 3 | L29: 2 | M29: 4 | N29: 3 | O29: No trigger verified | P29: Established mixed hospitality stack | Q29: Unknown | R29: Resort commerce consolidation | S29: Map Agilysys, RTP, Mashgin and Flaik by venue/property; confirm renewal dates. | T29: Agilysys; RTP; FreedomPay; Mashgin; Flaik | V29: Internal baseline only
A30: 26 | B30: P3 | C30: SLIM CHICKENS | D30: Avery Churchwell | E30: Tier 2 | F30: 250 | G30: =(H30/5*'Scoring Model'!$B$5+I30/5*'Scoring Model'!$B$6+J30/5*'Scoring Model'!$B$7+K30/5*'Scoring Model'!$B$8+L30/5*'Scoring Model'!$B$9+M30/5*'Scoring Model'!$B$10+N30/5*'Scoring Model'!$B$11)*100 -> 48 | H30: 3 | I30: 2 | J30: 2 | K30: 3 | L30: 1 | M30: 3 | N30: 2 | O30: Worldpay remains renewed through the reported three-year term. A Slim Chickens contact told Avery she plans to attend the FSTEC happy hour; RDS remains the required channel path. | P30: Established and expanding digital | Q30: Payments retained; Olo remains entrenched | R30: RDS-led relationship map; no active displacement trigger | S30: Avery to connect the attending Slim Chickens contact with Todd and the onsite Genius team for FSTEC; coordinate all follow-up with RDS and use the meeting to validate stakeholders and customer-defined modular needs, not to force a displacement pitch. | T30: PAR Brink; Olo Ordering/Dispatch/Rails/Switchboard/Sync | U30: Avery has a Slim Chickens contact expected at the FSTEC happy hour and will provide Genius attendee contact information because she will be in Europe. Todd is already working through RDS, which both parties agreed is the best joint route into Slim Chickens and Freddy's. | V30: High RM/channel intelligence dated 2026-09-04
